Traceback (most recent call last):
  File "C:\Users\admin\anaconda3\envs\ml_venv\lib\site-packages\jupyter_cache\executors\utils.py", line 58, in single_nb_execution
    executenb(
  File "C:\Users\admin\anaconda3\envs\ml_venv\lib\site-packages\nbclient\client.py", line 1305, in execute
    return NotebookClient(nb=nb, resources=resources, km=km, **kwargs).execute()
  File "C:\Users\admin\anaconda3\envs\ml_venv\lib\site-packages\jupyter_core\utils\__init__.py", line 166, in wrapped
    return loop.run_until_complete(inner)
  File "C:\Users\admin\anaconda3\envs\ml_venv\lib\asyncio\base_events.py", line 647, in run_until_complete
    return future.result()
  File "C:\Users\admin\anaconda3\envs\ml_venv\lib\site-packages\nbclient\client.py", line 705, in async_execute
    await self.async_execute_cell(
  File "C:\Users\admin\anaconda3\envs\ml_venv\lib\site-packages\nbclient\client.py", line 1058, in async_execute_cell
    await self._check_raise_for_error(cell, cell_index, exec_reply)
  File "C:\Users\admin\anaconda3\envs\ml_venv\lib\site-packages\nbclient\client.py", line 914, in _check_raise_for_error
    raise CellExecutionError.from_cell_and_msg(cell, exec_reply_content)
nbclient.exceptions.CellExecutionError: An error occurred while executing the following cell:
------------------
len(d2v_model.wv.vocab)
------------------


[1;31m---------------------------------------------------------------------------[0m
[1;31mAttributeError[0m                            Traceback (most recent call last)
Cell [1;32mIn[12], line 1[0m
[1;32m----> 1[0m [38;5;28mlen[39m([43md2v_model[49m[38;5;241;43m.[39;49m[43mwv[49m[38;5;241;43m.[39;49m[43mvocab[49m)

File [1;32m~\anaconda3\envs\ml_venv\lib\site-packages\gensim\models\keyedvectors.py:734[0m, in [0;36mKeyedVectors.vocab[1;34m(self)[0m
[0;32m    732[0m [38;5;129m@property[39m
[0;32m    733[0m [38;5;28;01mdef[39;00m [38;5;21mvocab[39m([38;5;28mself[39m):
[1;32m--> 734[0m     [38;5;28;01mraise[39;00m [38;5;167;01mAttributeError[39;00m(
[0;32m    735[0m         [38;5;124m"[39m[38;5;124mThe vocab attribute was removed from KeyedVector in Gensim 4.0.0.[39m[38;5;130;01m\n[39;00m[38;5;124m"[39m
[0;32m    736[0m         [38;5;124m"[39m[38;5;124mUse KeyedVector[39m[38;5;124m'[39m[38;5;124ms .key_to_index dict, .index_to_key list, and methods [39m[38;5;124m"[39m
[0;32m    737[0m         [38;5;124m"[39m[38;5;124m.get_vecattr(key, attr) and .set_vecattr(key, attr, new_val) instead.[39m[38;5;130;01m\n[39;00m[38;5;124m"[39m
[0;32m    738[0m         [38;5;124m"[39m[38;5;124mSee https://github.com/RaRe-Technologies/gensim/wiki/Migrating-from-Gensim-3.x-to-4[39m[38;5;124m"[39m
[0;32m    739[0m     )

[1;31mAttributeError[0m: The vocab attribute was removed from KeyedVector in Gensim 4.0.0.
Use KeyedVector's .key_to_index dict, .index_to_key list, and methods .get_vecattr(key, attr) and .set_vecattr(key, attr, new_val) instead.
See https://github.com/RaRe-Technologies/gensim/wiki/Migrating-from-Gensim-3.x-to-4

